Workbook

Sheet Raw Data
A1: Ride ID | B1: Date | C1: Pickup Location | D1: Drop-off Location | E1: Fare | F1: Payment Method | G1: Ride Status | H1: Rating | I1: Weekday | J1: Week No. | K1: Route | L1: Fare Tier
A2: R001 | B2: 46255 | C2: Gulberg | D2: DHA | E2: 713 | F2: Cash | G2: Completed | H2: 5 | I2: =TEXT(B2,"dddd") -> Friday | J2: =WEEKNUM(B2,2) -> 34 | K2: =C2&" -> "&D2 -> Gulberg -> DHA | L2: =IF(E2<Params!$B$5,"Low",IF(E2<=Params!$B$6,"Mid","High")) -> Mid
A3: R002 | B3: 46238 | C3: Gulberg | D3: Askari | E3: 215 | F3: Cash | G3: Completed | H3: 3 | I3: =TEXT(B3,"dddd") -> Tuesday | J3: =WEEKNUM(B3,2) -> 32 | K3: =C3&" -> "&D3 -> Gulberg -> Askari | L3: =IF(E3<Params!$B$5,"Low",IF(E3<=Params!$B$6,"Mid","High")) -> Low
A4: R003 | B4: 46251 | C4: Lahore | D4: Cantt | E4: 1009 | F4: Cash | G4: Completed | H4: 4 | I4: =TEXT(B4,"dddd") -> Monday | J4: =WEEKNUM(B4,2) -> 34 | K4: =C4&" -> "&D4 -> Lahore -> Cantt | L4: =IF(E4<Params!$B$5,"Low",IF(E4<=Params!$B$6,"Mid","High")) -> High
A5: R004 | B5: 46260 | C5: Lahore | D5: Model Town | E5: 1015 | F5: Card | G5: Completed | H5: 3 | I5: =TEXT(B5,"dddd") -> Wednesday | J5: =WEEKNUM(B5,2) -> 35 | K5: =C5&" -> "&D5 -> Lahore -> Model Town | L5: =IF(E5<Params!$B$5,"Low",IF(E5<=Params!$B$6,"Mid","High")) -> High
A6: R005 | B6: 46259 | C6: Bahria Town | D6: Gulberg | E6: 339 | F6: Card | G6: Completed | H6: 4 | I6: =TEXT(B6,"dddd") -> Tuesday | J6: =WEEKNUM(B6,2) -> 35 | K6: =C6&" -> "&D6 -> Bahria Town -> Gulberg | L6: =IF(E6<Params!$B$5,"Low",IF(E6<=Params!$B$6,"Mid","High")) -> Low
A7: R006 | B7: 46254 | C7: Johar Town | D7: DHA | E7: 1090 | F7: Wallet | G7: Completed | H7: 4 | I7: =TEXT(B7,"dddd") -> Thursday | J7: =WEEKNUM(B7,2) -> 34 | K7: =C7&" -> "&D7 -> Johar Town -> DHA | L7: =IF(E7<Params!$B$5,"Low",IF(E7<=Params!$B$6,"Mid","High")) -> High
A8: R007 | B8: 46237 | C8: Johar Town | D8: Faisal Town | E8: 543 | F8: Wallet | G8: Completed | H8: 5 | I8: =TEXT(B8,"dddd") -> Monday | J8: =WEEKNUM(B8,2) -> 32 | K8: =C8&" -> "&D8 -> Johar Town -> Faisal Town | L8: =IF(E8<Params!$B$5,"Low",IF(E8<=Params!$B$6,"Mid","High")) -> Low
A9: R008 | B9: 46242 | C9: Johar Town | D9: Gulberg | E9: 626 | F9: Cash | G9: Completed | H9: 4 | I9: =TEXT(B9,"dddd") -> Saturday | J9: =WEEKNUM(B9,2) -> 32 | K9: =C9&" -> "&D9 -> Johar Town -> Gulberg | L9: =IF(E9<Params!$B$5,"Low",IF(E9<=Params!$B$6,"Mid","High")) -> Mid
A10: R009 | B10: 46255 | C10: Bahria Town | D10: Model Town | E10: 908 | F10: Card | G10: Completed | H10: 4 | I10: =TEXT(B10,"dddd") -> Friday | J10: =WEEKNUM(B10,2) -> 34 | K10: =C10&" -> "&D10 -> Bahria Town -> Model Town | L10: =IF(E10<Params!$B$5,"Low",IF(E10<=Params!$B$6,"Mid","High")) -> High
A11: R010 | B11: 46257 | C11: Gulberg | D11: Model Town | E11: 651 | F11: Cash | G11: Completed | H11: 4 | I11: =TEXT(B11,"dddd") -> Sunday | J11: =WEEKNUM(B11,2) -> 34 | K11: =C11&" -> "&D11 -> Gulberg -> Model Town | L11: =IF(E11<Params!$B$5,"Low",IF(E11<=Params!$B$6,"Mid","High")) -> Mid
A12: R011 | B12: 46264 | C12: Model Town | D12: Faisal Town | E12: 264 | F12: Cash | G12: Cancelled | I12: =TEXT(B12,"dddd") -> Sunday | J12: =WEEKNUM(B12,2) -> 35 | K12: =C12&" -> "&D12 -> Model Town -> Faisal Town | L12: =IF(E12<Params!$B$5,"Low",IF(E12<=Params!$B$6,"Mid","High")) -> Low
A13: R012 | B13: 46260 | C13: Bahria Town | D13: Askari | E13: 698 | F13: Cash | G13: Completed | H13: 5 | I13: =TEXT(B13,"dddd") -> Wednesday | J13: =WEEKNUM(B13,2) -> 35 | K13: =C13&" -> "&D13 -> Bahria Town -> Askari | L13: =IF(E13<Params!$B$5,"Low",IF(E13<=Params!$B$6,"Mid","High")) -> Mid
A14: R013 | B14: 46263 | C14: Bahria Town | D14: Cantt | E14: 1172 | F14: Card | G14: Cancelled | I14: =TEXT(B14,"dddd") -> Saturday | J14: =WEEKNUM(B14,2) -> 35 | K14: =C14&" -> "&D14 -> Bahria Town -> Cantt | L14: =IF(E14<Params!$B$5,"Low",IF(E14<=Params!$B$6,"Mid","High")) -> High
A15: R014 | B15: 46255 | C15: Iqbal Town | D15: Model Town | E15: 692 | F15: Cash | G15: Completed | H15: 5 | I15: =TEXT(B15,"dddd") -> Friday | J15: =WEEKNUM(B15,2) -> 34 | K15: =C15&" -> "&D15 -> Iqbal Town -> Model Town | L15: =IF(E15<Params!$B$5,"Low",IF(E15<=Params!$B$6,"Mid","High")) -> Mid
A16: R015 | B16: 46252 | C16: Johar Town | D16: Askari | E16: 967 | F16: Card | G16: Completed | H16: 3 | I16: =TEXT(B16,"dddd") -> Tuesday | J16: =WEEKNUM(B16,2) -> 34 | K16: =C16&" -> "&D16 -> Johar Town -> Askari | L16: =IF(E16<Params!$B$5,"Low",IF(E16<=Params!$B$6,"Mid","High")) -> High
A17: R016 | B17: 46251 | C17: Iqbal Town | D17: Gulberg | E17: 246 | F17: Cash | G17: Completed | H17: 3 | I17: =TEXT(B17,"dddd") -> Monday | J17: =WEEKNUM(B17,2) -> 34 | K17: =C17&" -> "&D17 -> Iqbal Town -> Gulberg | L17: =IF(E17<Params!$B$5,"Low",IF(E17<=Params!$B$6,"Mid","High")) -> Low
A18: R017 | B18: 46260 | C18: Wapda Town | D18: Gulberg | E18: 938 | F18: Card | G18: Completed | H18: 4 | I18: =TEXT(B18,"dddd") -> Wednesday | J18: =WEEKNUM(B18,2) -> 35 | K18: =C18&" -> "&D18 -> Wapda Town -> Gulberg | L18: =IF(E18<Params!$B$5,"Low",IF(E18<=Params!$B$6,"Mid","High")) -> High
A19: R018 | B19: 46251 | C19: Johar Town | D19: DHA | E19: 384 | F19: Wallet | G19: Cancelled | I19: =TEXT(B19,"dddd") -> Monday | J19: =WEEKNUM(B19,2) -> 34 | K19: =C19&" -> "&D19 -> Johar Town -> DHA | L19: =IF(E19<Params!$B$5,"Low",IF(E19<=Params!$B$6,"Mid","High")) -> Low
A20: R019 | B20: 46259 | C20: Johar Town | D20: Faisal Town | E20: 378 | F20: Card | G20: Completed | H20: 4 | I20: =TEXT(B20,"dddd") -> Tuesday | J20: =WEEKNUM(B20,2) -> 35 | K20: =C20&" -> "&D20 -> Johar Town -> Faisal Town | L20: =IF(E20<Params!$B$5,"Low",IF(E20<=Params!$B$6,"Mid","High")) -> Low
A21: R020 | B21: 46235 | C21: Johar Town | D21: Model Town | E21: 1189 | F21: Cash | G21: Cancelled | I21: =TEXT(B21,"dddd") -> Saturday | J21: =WEEKNUM(B21,2) -> 31 | K21: =C21&" -> "&D21 -> Johar Town -> Model Town | L21: =IF(E21<Params!$B$5,"Low",IF(E21<=Params!$B$6,"Mid","High")) -> High
A22: R021 | B22: 46244 | C22: Model Town | D22: Model Town | E22: 915 | F22: Cash | G22: Completed | H22: 5 | I22: =TEXT(B22,"dddd") -> Monday | J22: =WEEKNUM(B22,2) -> 33 | K22: =C22&" -> "&D22 -> Model Town -> Model Town | L22: =IF(E22<Params!$B$5,"Low",IF(E22<=Params!$B$6,"Mid","High")) -> High
A23: R022 | B23: 46264 | C23: Lahore | D23: Faisal Town | E23: 1150 | F23: Cash | G23: Completed | H23: 4 | I23: =TEXT(B23,"dddd") -> Sunday | J23: =WEEKNUM(B23,2) -> 35 | K23: =C23&" -> "&D23 -> Lahore -> Faisal Town | L23: =IF(E23<Params!$B$5,"Low",IF(E23<=Params!$B$6,"Mid","High")) -> High
A24: R023 | B24: 46263 | C24: Johar Town | D24: Cantt | E24: 268 | F24: Cash | G24: Cancelled | I24: =TEXT(B24,"dddd") -> Saturday | J24: =WEEKNUM(B24,2) -> 35 | K24: =C24&" -> "&D24 -> Johar Town -> Cantt | L24: =IF(E24<Params!$B$5,"Low",IF(E24<=Params!$B$6,"Mid","High")) -> Low
A25: R024 | B25: 46237 | C25: Gulberg | D25: Airport | E25: 291 | F25: Wallet | G25: Completed | H25: 3 | I25: =TEXT(B25,"dddd") -> Monday | J25: =WEEKNUM(B25,2) -> 32 | K25: =C25&" -> "&D25 -> Gulberg -> Airport | L25: =IF(E25<Params!$B$5,"Low",IF(E25<=Params!$B$6,"Mid","High")) -> Low
A26: R025 | B26: 46256 | C26: Iqbal Town | D26: Model Town | E26: 692 | F26: Wallet | G26: Cancelled | I26: =TEXT(B26,"dddd") -> Saturday | J26: =WEEKNUM(B26,2) -> 34 | K26: =C26&" -> "&D26 -> Iqbal Town -> Model Town | L26: =IF(E26<Params!$B$5,"Low",IF(E26<=Params!$B$6,"Mid","High")) -> Mid
A27: R026 | B27: 46248 | C27: Model Town | D27: Cantt | E27: 788 | F27: Card | G27: Cancelled | I27: =TEXT(B27,"dddd") -> Friday | J27: =WEEKNUM(B27,2) -> 33 | K27: =C27&" -> "&D27 -> Model Town -> Cantt | L27: =IF(E27<Params!$B$5,"Low",IF(E27<=Params!$B$6,"Mid","High")) -> Mid
A28: R027 | B28: 46255 | C28: Bahria Town | D28: Airport | E28: 1074 | F28: Cash | G28: Completed | H28: 3 | I28: =TEXT(B28,"dddd") -> Friday | J28: =WEEKNUM(B28,2) -> 34 | K28: =C28&" -> "&D28 -> Bahria Town -> Airport | L28: =IF(E28<Params!$B$5,"Low",IF(E28<=Params!$B$6,"Mid","High")) -> High
A29: R028 | B29: 46245 | C29: Lahore | D29: Cantt | E29: 601 | F29: Cash | G29: Completed | H29: 5 | I29: =TEXT(B29,"dddd") -> Tuesday | J29: =WEEKNUM(B29,2) -> 33 | K29: =C29&" -> "&D29 -> Lahore -> Cantt | L29: =IF(E29<Params!$B$5,"Low",IF(E29<=Params!$B$6,"Mid","High")) -> Mid
A30: R029 | B30: 46236 | C30: Model Town | D30: Gulberg | E30: 214 | F30: Card | G30: Completed | H30: 3 | I30: =TEXT(B30,"dddd") -> Sunday | J30: =WEEKNUM(B30,2) -> 31 | K30: =C30&" -> "&D30 -> Model Town -> Gulberg | L30: =IF(E30<Params!$B$5,"Low",IF(E30<=Params!$B$6,"Mid","High")) -> Low
A31: R030 | B31: 46243 | C31: Iqbal Town | D31: Cantt | E31: 420 | F31: Wallet | G31: Cancelled | I31: =TEXT(B31,"dddd") -> Sunday | J31: =WEEKNUM(B31,2) -> 32 | K31: =C31&" -> "&D31 -> Iqbal Town -> Cantt | L31: =IF(E31<Params!$B$5,"Low",IF(E31<=Params!$B$6,"Mid","High")) -> Low
A32: R031 | B32: 46253 | C32: Iqbal Town | D32: Cantt | E32: 1118 | F32: Card | G32: Completed | H32: 3 | I32: =TEXT(B32,"dddd") -> Wednesday | J32: =WEEKNUM(B32,2) -> 34 | K32: =C32&" -> "&D32 -> Iqbal Town -> Cantt | L32: =IF(E32<Params!$B$5,"Low",IF(E32<=Params!$B$6,"Mid","High")) -> High
A33: R032 | B33: 46256 | C33: Wapda Town | D33: Faisal Town | E33: 1017 | F33: Card | G33: Completed | H33: 5 | I33: =TEXT(B33,"dddd") -> Saturday | J33: =WEEKNUM(B33,2) -> 34 | K33: =C33&" -> "&D33 -> Wapda Town -> Faisal Town | L33: =IF(E33<Params!$B$5,"Low",IF(E33<=Params!$B$6,"Mid","High")) -> High
A34: R033 | B34: 46236 | C34: Gulberg | D34: DHA | E34: 974 | F34: Wallet | G34: Completed | H34: 3 | I34: =TEXT(B34,"dddd") -> Sunday | J34: =WEEKNUM(B34,2) -> 31 | K34: =C34&" -> "&D34 -> Gulberg -> DHA | L34: =IF(E34<Params!$B$5,"Low",IF(E34<=Params!$B$6,"Mid","High")) -> High
A35: R034 | B35: 46242 | C35: Model Town | D35: Cantt | E35: 1068 | F35: Cash | G35: Completed | H35: 4 | I35: =TEXT(B35,"dddd") -> Saturday | J35: =WEEKNUM(B35,2) -> 32 | K35: =C35&" -> "&D35 -> Model Town -> Cantt | L35: =IF(E35<Params!$B$5,"Low",IF(E35<=Params!$B$6,"Mid","High")) -> High
A36: R035 | B36: 46249 | C36: Model Town | D36: Gulberg | E36: 1057 | F36: Wallet | G36: Completed | H36: 5 | I36: =TEXT(B36,"dddd") -> Saturday | J36: =WEEKNUM(B36,2) -> 33 | K36: =C36&" -> "&D36 -> Model Town -> Gulberg | L36: =IF(E36<Params!$B$5,"Low",IF(E36<=Params!$B$6,"Mid","High")) -> High
A37: R036 | B37: 46252 | C37: Lahore | D37: Gulberg | E37: 634 | F37: Cash | G37: Completed | H37: 4 | I37: =TEXT(B37,"dddd") -> Tuesday | J37: =WEEKNUM(B37,2) -> 34 | K37: =C37&" -> "&D37 -> Lahore -> Gulberg | L37: =IF(E37<Params!$B$5,"Low",IF(E37<=Params!$B$6,"Mid","High")) -> Mid
A38: R037 | B38: 46241 | C38: Wapda Town | D38: DHA | E38: 487 | F38: Card | G38: Completed | H38: 4 | I38: =TEXT(B38,"dddd") -> Friday | J38: =WEEKNUM(B38,2) -> 32 | K38: =C38&" -> "&D38 -> Wapda Town -> DHA | L38: =IF(E38<Params!$B$5,"Low",IF(E38<=Params!$B$6,"Mid","High")) -> Low
A39: R038 | B39: 46243 | C39: Iqbal Town | D39: Township | E39: 1016 | F39: Wallet | G39: Cancelled | I39: =TEXT(B39,"dddd") -> Sunday | J39: =WEEKNUM(B39,2) -> 32 | K39: =C39&" -> "&D39 -> Iqbal Town -> Township | L39: =IF(E39<Params!$B$5,"Low",IF(E39<=Params!$B$6,"Mid","High")) -> High
A40: R039 | B40: 46260 | C40: Iqbal Town | D40: Model Town | E40: 538 | F40: Card | G40: Completed | H40: 3 | I40: =TEXT(B40,"dddd") -> Wednesday | J40: =WEEKNUM(B40,2) -> 35 | K40: =C40&" -> "&D40 -> Iqbal Town -> Model Town | L40: =IF(E40<Params!$B$5,"Low",IF(E40<=Params!$B$6,"Mid","High")) -> Low
...

Sheet Params
A1: Model Parameters
A2: Fare-tier thresholds = 33rd / 67th percentile of completed-ride fares, computed once from the dataset (edit the yellow cells to re-tier).
A4: Parameter | B4: Value
A5: Low/Mid fare threshold (33rd pct. of completed fares) | B5: 548
A6: Mid/High fare threshold (67th pct. of completed fares) | B6: 822

Sheet Date Table
A1: Date Table
A2: Dedicated date dimension for August 2026 (the full span of the ride log).
A4: Date | B4: Day | C4: Weekday | D4: Week No. | E4: Month | F4: Is Weekend
A5: 46235 | B5: =DAY(A5) -> 1 | C5: =TEXT(A5,"dddd") -> Saturday | D5: =WEEKNUM(A5,2) -> 31 | E5: =TEXT(A5,"mmmm yyyy") -> August 2026 | F5: =IF(WEEKDAY(A5,2)>5,"Yes","No") -> Yes
A6: 46236 | B6: =DAY(A6) -> 2 | C6: =TEXT(A6,"dddd") -> Sunday | D6: =WEEKNUM(A6,2) -> 31 | E6: =TEXT(A6,"mmmm yyyy") -> August 2026 | F6: =IF(WEEKDAY(A6,2)>5,"Yes","No") -> Yes
A7: 46237 | B7: =DAY(A7) -> 3 | C7: =TEXT(A7,"dddd") -> Monday | D7: =WEEKNUM(A7,2) -> 32 | E7: =TEXT(A7,"mmmm yyyy") -> August 2026 | F7: =IF(WEEKDAY(A7,2)>5,"Yes","No") -> No
A8: 46238 | B8: =DAY(A8) -> 4 | C8: =TEXT(A8,"dddd") -> Tuesday | D8: =WEEKNUM(A8,2) -> 32 | E8: =TEXT(A8,"mmmm yyyy") -> August 2026 | F8: =IF(WEEKDAY(A8,2)>5,"Yes","No") -> No
A9: 46239 | B9: =DAY(A9) -> 5 | C9: =TEXT(A9,"dddd") -> Wednesday | D9: =WEEKNUM(A9,2) -> 32 | E9: =TEXT(A9,"mmmm yyyy") -> August 2026 | F9: =IF(WEEKDAY(A9,2)>5,"Yes","No") -> No
A10: 46240 | B10: =DAY(A10) -> 6 | C10: =TEXT(A10,"dddd") -> Thursday | D10: =WEEKNUM(A10,2) -> 32 | E10: =TEXT(A10,"mmmm yyyy") -> August 2026 | F10: =IF(WEEKDAY(A10,2)>5,"Yes","No") -> No
A11: 46241 | B11: =DAY(A11) -> 7 | C11: =TEXT(A11,"dddd") -> Friday | D11: =WEEKNUM(A11,2) -> 32 | E11: =TEXT(A11,"mmmm yyyy") -> August 2026 | F11: =IF(WEEKDAY(A11,2)>5,"Yes","No") -> No
A12: 46242 | B12: =DAY(A12) -> 8 | C12: =TEXT(A12,"dddd") -> Saturday | D12: =WEEKNUM(A12,2) -> 32 | E12: =TEXT(A12,"mmmm yyyy") -> August 2026 | F12: =IF(WEEKDAY(A12,2)>5,"Yes","No") -> Yes
A13: 46243 | B13: =DAY(A13) -> 9 | C13: =TEXT(A13,"dddd") -> Sunday | D13: =WEEKNUM(A13,2) -> 32 | E13: =TEXT(A13,"mmmm yyyy") -> August 2026 | F13: =IF(WEEKDAY(A13,2)>5,"Yes","No") -> Yes
A14: 46244 | B14: =DAY(A14) -> 10 | C14: =TEXT(A14,"dddd") -> Monday | D14: =WEEKNUM(A14,2) -> 33 | E14: =TEXT(A14,"mmmm yyyy") -> August 2026 | F14: =IF(WEEKDAY(A14,2)>5,"Yes","No") -> No
A15: 46245 | B15: =DAY(A15) -> 11 | C15: =TEXT(A15,"dddd") -> Tuesday | D15: =WEEKNUM(A15,2) -> 33 | E15: =TEXT(A15,"mmmm yyyy") -> August 2026 | F15: =IF(WEEKDAY(A15,2)>5,"Yes","No") -> No
A16: 46246 | B16: =DAY(A16) -> 12 | C16: =TEXT(A16,"dddd") -> Wednesday | D16: =WEEKNUM(A16,2) -> 33 | E16: =TEXT(A16,"mmmm yyyy") -> August 2026 | F16: =IF(WEEKDAY(A16,2)>5,"Yes","No") -> No
... A35: 46265 | B35: =DAY(A35) -> 31 | C35: =TEXT(A35,"dddd") -> Monday | D35: =WEEKNUM(A35,2) -> 36 | E35: =TEXT(A35,"mmmm yyyy") -> August 2026 | F35: =IF(WEEKDAY(A35,2)>5,"Yes","No") -> No

Sheet KPI Summary
A1: Core KPI Summary
A2: Equivalent of the Power BI measures table — validate these against your DAX.
A4: Measure | B4: Value | C4: Notes
A5: Total Rides | B5: =COUNTA('Raw Data'!$A$2:$A$121) -> 120 | C5: All logged rides
A6: Completed Rides | B6: =COUNTIF('Raw Data'!$G$2:$G$121,"Completed") -> 96 | C6: Status = Completed
A7: Cancelled Rides | B7: =COUNTIF('Raw Data'!$G$2:$G$121,"Cancelled") -> 24 | C7: Status = Cancelled
A8: Completion Rate | B8: =B6/B5 -> 0.8
A9: Cancellation Rate | B9: =B7/B5 -> 0.2
A10: Total Revenue | B10: =SUMIF('Raw Data'!$G$2:$G$121,"Completed",'Raw Data'!$E$2:$E$121) -> 65427 | C10: Completed rides only
A11: Average Fare (Completed) | B11: =AVERAGEIF('Raw Data'!$G$2:$G$121,"Completed",'Raw Data'!$E$2:$E$121) -> 681.53125
A12: Revenue per Completed Ride | B12: =B10/B6 -> 681.53125 | C12: Total Revenue divided by Completed Rides (same as Avg Fare here since no surge/tips)
A13: Average Rating | B13: =AVERAGE('Raw Data'!$H$2:$H$121) -> 3.9583333 | C13: Ratings only exist for completed rides

Sheet Weekday Analysis
A1: Cancellation & Demand by Weekday
A2: Hour-of-day data is not available in this dataset; weekday is the finest time grain we can analyze.
A4: Weekday | B4: Total Rides | C4: Completed | D4: Cancelled | E4: Cancellation Rate | F4: Revenue
A5: Monday | B5: =COUNTIF('Raw Data'!$I$2:$I$121,A5) -> 20 | C5: =COUNTIFS('Raw Data'!$I$2:$I$121,A5,'Raw Data'!$G$2:$G$121,"Completed") -> 16 | D5: =COUNTIFS('Raw Data'!$I$2:$I$121,A5,'Raw Data'!$G$2:$G$121,"Cancelled") -> 4 | E5: =D5/B5 -> 0.2 | F5: =SUMIFS('Raw Data'!$E$2:$E$121,'Raw Data'!$I$2:$I$121,A5,'Raw Data'!$G$2:$G$121,"Completed") -> 10323
A6: Tuesday | B6: =COUNTIF('Raw Data'!$I$2:$I$121,A6) -> 13 | C6: =COUNTIFS('Raw Data'!$I$2:$I$121,A6,'Raw Data'!$G$2:$G$121,"Completed") -> 12 | D6: =COUNTIFS('Raw Data'!$I$2:$I$121,A6,'Raw Data'!$G$2:$G$121,"Cancelled") -> 1 | E6: =D6/B6 -> 0.076923077 | F6: =SUMIFS('Raw Data'!$E$2:$E$121,'Raw Data'!$I$2:$I$121,A6,'Raw Data'!$G$2:$G$121,"Completed") -> 7546
A7: Wednesday | B7: =COUNTIF('Raw Data'!$I$2:$I$121,A7) -> 18 | C7: =COUNTIFS('Raw Data'!$I$2:$I$121,A7,'Raw Data'!$G$2:$G$121,"Completed") -> 17 | D7: =COUNTIFS('Raw Data'!$I$2:$I$121,A7,'Raw Data'!$G$2:$G$121,"Cancelled") -> 1 | E7: =D7/B7 -> 0.055555556 | F7: =SUMIFS('Raw Data'!$E$2:$E$121,'Raw Data'!$I$2:$I$121,A7,'Raw Data'!$G$2:$G$121,"Completed") -> 11667
A8: Thursday | B8: =COUNTIF('Raw Data'!$I$2:$I$121,A8) -> 9 | C8: =COUNTIFS('Raw Data'!$I$2:$I$121,A8,'Raw Data'!$G$2:$G$121,"Completed") -> 9 | D8: =COUNTIFS('Raw Data'!$I$2:$I$121,A8,'Raw Data'!$G$2:$G$121,"Cancelled") -> 0 | E8: =D8/B8 -> 0 | F8: =SUMIFS('Raw Data'!$E$2:$E$121,'Raw Data'!$I$2:$I$121,A8,'Raw Data'!$G$2:$G$121,"Completed") -> 5483
A9: Friday | B9: =COUNTIF('Raw Data'!$I$2:$I$121,A9) -> 14 | C9: =COUNTIFS('Raw Data'!$I$2:$I$121,A9,'Raw Data'!$G$2:$G$121,"Completed") -> 11 | D9: =COUNTIFS('Raw Data'!$I$2:$I$121,A9,'Raw Data'!$G$2:$G$121,"Cancelled") -> 3 | E9: =D9/B9 -> 0.21428571 | F9: =SUMIFS('Raw Data'!$E$2:$E$121,'Raw Data'!$I$2:$I$121,A9,'Raw Data'!$G$2:$G$121,"Completed") -> 9176
A10: Saturday | B10: =COUNTIF('Raw Data'!$I$2:$I$121,A10) -> 23 | C10: =COUNTIFS('Raw Data'!$I$2:$I$121,A10,'Raw Data'!$G$2:$G$121,"Completed") -> 14 | D10: =COUNTIFS('Raw Data'!$I$2:$I$121,A10,'Raw Data'!$G$2:$G$121,"Cancelled") -> 9 | E10: =D10/B10 -> 0.39130435 | F10: =SUMIFS('Raw Data'!$E$2:$E$121,'Raw Data'!$I$2:$I$121,A10,'Raw Data'!$G$2:$G$121,"Completed") -> 9322
A11: Sunday | B11: =COUNTIF('Raw Data'!$I$2:$I$121,A11) -> 23 | C11: =COUNTIFS('Raw Data'!$I$2:$I$121,A11,'Raw Data'!$G$2:$G$121,"Completed") -> 17 | D11: =COUNTIFS('Raw Data'!$I$2:$I$121,A11,'Raw Data'!$G$2:$G$121,"Cancelled") -> 6 | E11: =D11/B11 -> 0.26086957 | F11: =SUMIFS('Raw Data'!$E$2:$E$121,'Raw Data'!$I$2:$I$121,A11,'Raw Data'!$G$2:$G$121,"Completed") -> 11910

Sheet Weekly Trend
A1: Week-over-Week Trend
A2: Only one calendar month of data exists, so trend is shown week-over-week rather than month-over-month. Week 31 is partial (2 days).
A4: Week No. | B4: Total Rides | C4: Completed | D4: Cancelled | E4: Cancellation Rate | F4: Revenue | G4: Revenue vs Prior Week | H4: % Change vs Prior Week
A5: 31 | B5: =COUNTIF('Raw Data'!$J$2:$J$121,A5) -> 13 | C5: =COUNTIFS('Raw Data'!$J$2:$J$121,A5,'Raw Data'!$G$2:$G$121,"Completed") -> 9 | D5: =COUNTIFS('Raw Data'!$J$2:$J$121,A5,'Raw Data'!$G$2:$G$121,"Cancelled") -> 4 | E5: =D5/B5 -> 0.30769231 | F5: =SUMIFS('Raw Data'!$E$2:$E$121,'Raw Data'!$J$2:$J$121,A5,'Raw Data'!$G$2:$G$121,"Completed") -> 5342 | G5: ="" | H5: =""
A6: 32 | B6: =COUNTIF('Raw Data'!$J$2:$J$121,A6) -> 28 | C6: =COUNTIFS('Raw Data'!$J$2:$J$121,A6,'Raw Data'!$G$2:$G$121,"Completed") -> 24 | D6: =COUNTIFS('Raw Data'!$J$2:$J$121,A6,'Raw Data'!$G$2:$G$121,"Cancelled") -> 4 | E6: =D6/B6 -> 0.14285714 | F6: =SUMIFS('Raw Data'!$E$2:$E$121,'Raw Data'!$J$2:$J$121,A6,'Raw Data'!$G$2:$G$121,"Completed") -> 15241 | G6: =F6-F5 -> 9899 | H6: =IF(F5=0,"",(F6-F5)/F5) -> 1.8530513
A7: 33 | B7: =COUNTIF('Raw Data'!$J$2:$J$121,A7) -> 18 | C7: =COUNTIFS('Raw Data'!$J$2:$J$121,A7,'Raw Data'!$G$2:$G$121,"Completed") -> 15 | D7: =COUNTIFS('Raw Data'!$J$2:$J$121,A7,'Raw Data'!$G$2:$G$121,"Cancelled") -> 3 | E7: =D7/B7 -> 0.16666667 | F7: =SUMIFS('Raw Data'!$E$2:$E$121,'Raw Data'!$J$2:$J$121,A7,'Raw Data'!$G$2:$G$121,"Completed") -> 10381 | G7: =F7-F6 -> -4860 | H7: =IF(F6=0,"",(F7-F6)/F6) -> -0.31887671
A8: 34 | B8: =COUNTIF('Raw Data'!$J$2:$J$121,A8) -> 36 | C8: =COUNTIFS('Raw Data'!$J$2:$J$121,A8,'Raw Data'!$G$2:$G$121,"Completed") -> 30 | D8: =COUNTIFS('Raw Data'!$J$2:$J$121,A8,'Raw Data'!$G$2:$G$121,"Cancelled") -> 6 | E8: =D8/B8 -> 0.16666667 | F8: =SUMIFS('Raw Data'!$E$2:$E$121,'Raw Data'!$J$2:$J$121,A8,'Raw Data'!$G$2:$G$121,"Completed") -> 21188 | G8: =F8-F7 -> 10807 | H8: =IF(F7=0,"",(F8-F7)/F7) -> 1.0410365
A9: 35 | B9: =COUNTIF('Raw Data'!$J$2:$J$121,A9) -> 25 | C9: =COUNTIFS('Raw Data'!$J$2:$J$121,A9,'Raw Data'!$G$2:$G$121,"Completed") -> 18 | D9: =COUNTIFS('Raw Data'!$J$2:$J$121,A9,'Raw Data'!$G$2:$G$121,"Cancelled") -> 7 | E9: =D9/B9 -> 0.28 | F9: =SUMIFS('Raw Data'!$E$2:$E$121,'Raw Data'!$J$2:$J$121,A9,'Raw Data'!$G$2:$G$121,"Completed") -> 13275 | G9: =F9-F8 -> -7913 | H9: =IF(F8=0,"",(F9-F8)/F8) -> -0.37346611

Sheet Location Analysis
A1: Revenue & Cancellation by Pickup Location
A2: Ranked by revenue contribution; use to spot high-volume/low-revenue and low-volume/high-fare segments.
A4: Pickup Location | B4: Total Rides | C4: Completed | D4: Cancelled | E4: Cancellation Rate | F4: Revenue | G4: Revenue % of Total | H4: Revenue Rank | I4: Avg Fare (Completed)
A5: Bahria Town | B5: =COUNTIF('Raw Data'!$C$2:$C$121,A5) -> 15 | C5: =COUNTIFS('Raw Data'!$C$2:$C$121,A5,'Raw Data'!$G$2:$G$121,"Completed") -> 12 | D5: =COUNTIFS('Raw Data'!$C$2:$C$121,A5,'Raw Data'!$G$2:$G$121,"Cancelled") -> 3 | E5: =D5/B5 -> 0.2 | F5: =SUMIFS('Raw Data'!$E$2:$E$121,'Raw Data'!$C$2:$C$121,A5,'Raw Data'!$G$2:$G$121,"Completed") -> 8145 | G5: =F5/'KPI Summary'!$B$10 -> 0.12448989 | H5: =RANK(F5,$F$5:$F$12) -> 6 | I5: =IFERROR(F5/C5,0) -> 678.75
A6: DHA | B6: =COUNTIF('Raw Data'!$C$2:$C$121,A6) -> 7 | C6: =COUNTIFS('Raw Data'!$C$2:$C$121,A6,'Raw Data'!$G$2:$G$121,"Completed") -> 6 | D6: =COUNTIFS('Raw Data'!$C$2:$C$121,A6,'Raw Data'!$G$2:$G$121,"Cancelled") -> 1 | E6: =D6/B6 -> 0.14285714 | F6: =SUMIFS('Raw Data'!$E$2:$E$121,'Raw Data'!$C$2:$C$121,A6,'Raw Data'!$G$2:$G$121,"Completed") -> 3514 | G6: =F6/'KPI Summary'!$B$10 -> 0.053708714 | H6: =RANK(F6,$F$5:$F$12) -> 8 | I6: =IFERROR(F6/C6,0) -> 585.66667
A7: Gulberg | B7: =COUNTIF('Raw Data'!$C$2:$C$121,A7) -> 15 | C7: =COUNTIFS('Raw Data'!$C$2:$C$121,A7,'Raw Data'!$G$2:$G$121,"Completed") -> 14 | D7: =COUNTIFS('Raw Data'!$C$2:$C$121,A7,'Raw Data'!$G$2:$G$121,"Cancelled") -> 1 | E7: =D7/B7 -> 0.066666667 | F7: =SUMIFS('Raw Data'!$E$2:$E$121,'Raw Data'!$C$2:$C$121,A7,'Raw Data'!$G$2:$G$121,"Completed") -> 8757 | G7: =F7/'KPI Summary'!$B$10 -> 0.13384383 | H7: =RANK(F7,$F$5:$F$12) -> 4 | I7: =IFERROR(F7/C7,0) -> 625.5
A8: Iqbal Town | B8: =COUNTIF('Raw Data'!$C$2:$C$121,A8) -> 15 | C8: =COUNTIFS('Raw Data'!$C$2:$C$121,A8,'Raw Data'!$G$2:$G$121,"Completed") -> 12 | D8: =COUNTIFS('Raw Data'!$C$2:$C$121,A8,'Raw Data'!$G$2:$G$121,"Cancelled") -> 3 | E8: =D8/B8 -> 0.2 | F8: =SUMIFS('Raw Data'!$E$2:$E$121,'Raw Data'!$C$2:$C$121,A8,'Raw Data'!$G$2:$G$121,"Completed") -> 8466 | G8: =F8/'KPI Summary'!$B$10 -> 0.12939612 | H8: =RANK(F8,$F$5:$F$12) -> 5 | I8: =IFERROR(F8/C8,0) -> 705.5
A9: Johar Town | B9: =COUNTIF('Raw Data'!$C$2:$C$121,A9) -> 21 | C9: =COUNTIFS('Raw Data'!$C$2:$C$121,A9,'Raw Data'!$G$2:$G$121,"Completed") -> 17 | D9: =COUNTIFS('Raw Data'!$C$2:$C$121,A9,'Raw Data'!$G$2:$G$121,"Cancelled") -> 4 | E9: =D9/B9 -> 0.19047619 | F9: =SUMIFS('Raw Data'!$E$2:$E$121,'Raw Data'!$C$2:$C$121,A9,'Raw Data'!$G$2:$G$121,"Completed") -> 11323 | G9: =F9/'KPI Summary'!$B$10 -> 0.17306311 | H9: =RANK(F9,$F$5:$F$12) -> 1 | I9: =IFERROR(F9/C9,0) -> 666.05882
A10: Lahore | B10: =COUNTIF('Raw Data'!$C$2:$C$121,A10) -> 10 | C10: =COUNTIFS('Raw Data'!$C$2:$C$121,A10,'Raw Data'!$G$2:$G$121,"Completed") -> 7 | D10: =COUNTIFS('Raw Data'!$C$2:$C$121,A10,'Raw Data'!$G$2:$G$121,"Cancelled") -> 3 | E10: =D10/B10 -> 0.3 | F10: =SUMIFS('Raw Data'!$E$2:$E$121,'Raw Data'!$C$2:$C$121,A10,'Raw Data'!$G$2:$G$121,"Completed") -> 5281 | G10: =F10/'KPI Summary'!$B$10 -> 0.080715912 | H10: =RANK(F10,$F$5:$F$12) -> 7 | I10: =IFERROR(F10/C10,0) -> 754.42857
A11: Model Town | B11: =COUNTIF('Raw Data'!$C$2:$C$121,A11) -> 19 | C11: =COUNTIFS('Raw Data'!$C$2:$C$121,A11,'Raw Data'!$G$2:$G$121,"Completed") -> 14 | D11: =COUNTIFS('Raw Data'!$C$2:$C$121,A11,'Raw Data'!$G$2:$G$121,"Cancelled") -> 5 | E11: =D11/B11 -> 0.26315789 | F11: =SUMIFS('Raw Data'!$E$2:$E$121,'Raw Data'!$C$2:$C$121,A11,'Raw Data'!$G$2:$G$121,"Completed") -> 10139 | G11: =F11/'KPI Summary'!$B$10 -> 0.1549666 | H11: =RANK(F11,$F$5:$F$12) -> 2 | I11: =IFERROR(F11/C11,0) -> 724.21429
A12: Wapda Town | B12: =COUNTIF('Raw Data'!$C$2:$C$121,A12) -> 18 | C12: =COUNTIFS('Raw Data'!$C$2:$C$121,A12,'Raw Data'!$G$2:$G$121,"Completed") -> 14 | D12: =COUNTIFS('Raw Data'!$C$2:$C$121,A12,'Raw Data'!$G$2:$G$121,"Cancelled") -> 4 | E12: =D12/B12 -> 0.22222222 | F12: =SUMIFS('Raw Data'!$E$2:$E$121,'Raw Data'!$C$2:$C$121,A12,'Raw Data'!$G$2:$G$121,"Completed") -> 9802 | G12: =F12/'KPI Summary'!$B$10 -> 0.14981583 | H12: =RANK(F12,$F$5:$F$12) -> 3 | I12: =IFERROR(F12/C12,0) -> 700.14286

Sheet Route Analysis
A1: Route-Level Analysis (Top Corridors)
A2: No ride-type or distance field exists, so pickup->drop-off route is the closest available segment. Only routes with 3+ rides are shown for statistical stability.
A4: Route | B4: Total Rides | C4: Completed | D4: Cancelled | E4: Cancellation Rate | F4: Revenue | G4: Avg Fare (Completed)
A5: Bahria Town -> Airport | B5: =COUNTIF('Raw Data'!$K$2:$K$121,A5) -> 3 | C5: =COUNTIFS('Raw Data'!$K$2:$K$121,A5,'Raw Data'!$G$2:$G$121,"Completed") -> 2 | D5: =COUNTIFS('Raw Data'!$K$2:$K$121,A5,'Raw Data'!$G$2:$G$121,"Cancelled") -> 1 | E5: =D5/B5 -> 0.33333333 | F5: =SUMIFS('Raw Data'!$E$2:$E$121,'Raw Data'!$K$2:$K$121,A5,'Raw Data'!$G$2:$G$121,"Completed") -> 2128 | G5: =IFERROR(F5/C5,0) -> 1064
A6: Bahria Town -> Cantt | B6: =COUNTIF('Raw Data'!$K$2:$K$121,A6) -> 4 | C6: =COUNTIFS('Raw Data'!$K$2:$K$121,A6,'Raw Data'!$G$2:$G$121,"Completed") -> 3 | D6: =COUNTIFS('Raw Data'!$K$2:$K$121,A6,'Raw Data'!$G$2:$G$121,"Cancelled") -> 1 | E6: =D6/B6 -> 0.25 | F6: =SUMIFS('Raw Data'!$E$2:$E$121,'Raw Data'!$K$2:$K$121,A6,'Raw Data'!$G$2:$G$121,"Completed") -> 1641 | G6: =IFERROR(F6/C6,0) -> 547
A7: Gulberg -> Askari | B7: =COUNTIF('Raw Data'!$K$2:$K$121,A7) -> 4 | C7: =COUNTIFS('Raw Data'!$K$2:$K$121,A7,'Raw Data'!$G$2:$G$121,"Completed") -> 4 | D7: =COUNTIFS('Raw Data'!$K$2:$K$121,A7,'Raw Data'!$G$2:$G$121,"Cancelled") -> 0 | E7: =D7/B7 -> 0 | F7: =SUMIFS('Raw Data'!$E$2:$E$121,'Raw Data'!$K$2:$K$121,A7,'Raw Data'!$G$2:$G$121,"Completed") -> 2595 | G7: =IFERROR(F7/C7,0) -> 648.75
A8: Gulberg -> Model Town | B8: =COUNTIF('Raw Data'!$K$2:$K$121,A8) -> 3 | C8: =COUNTIFS('Raw Data'!$K$2:$K$121,A8,'Raw Data'!$G$2:$G$121,"Completed") -> 3 | D8: =COUNTIFS('Raw Data'!$K$2:$K$121,A8,'Raw Data'!$G$2:$G$121,"Cancelled") -> 0 | E8: =D8/B8 -> 0 | F8: =SUMIFS('Raw Data'!$E$2:$E$121,'Raw Data'!$K$2:$K$121,A8,'Raw Data'!$G$2:$G$121,"Completed") -> 2079 | G8: =IFERROR(F8/C8,0) -> 693
A9: Iqbal Town -> Cantt | B9: =COUNTIF('Raw Data'!$K$2:$K$121,A9) -> 3 | C9: =COUNTIFS('Raw Data'!$K$2:$K$121,A9,'Raw Data'!$G$2:$G$121,"Completed") -> 2 | D9: =COUNTIFS('Raw Data'!$K$2:$K$121,A9,'Raw Data'!$G$2:$G$121,"Cancelled") -> 1 | E9: =D9/B9 -> 0.33333333 | F9: =SUMIFS('Raw Data'!$E$2:$E$121,'Raw Data'!$K$2:$K$121,A9,'Raw Data'!$G$2:$G$121,"Completed") -> 1994 | G9: =IFERROR(F9/C9,0) -> 997
A10: Iqbal Town -> Gulberg | B10: =COUNTIF('Raw Data'!$K$2:$K$121,A10) -> 3 | C10: =COUNTIFS('Raw Data'!$K$2:$K$121,A10,'Raw Data'!$G$2:$G$121,"Completed") -> 3 | D10: =COUNTIFS('Raw Data'!$K$2:$K$121,A10,'Raw Data'!$G$2:$G$121,"Cancelled") -> 0 | E10: =D10/B10 -> 0 | F10: =SUMIFS('Raw Data'!$E$2:$E$121,'Raw Data'!$K$2:$K$121,A10,'Raw Data'!$G$2:$G$121,"Completed") -> 829 | G10: =IFERROR(F10/C10,0) -> 276.33333
A11: Iqbal Town -> Model Town | B11: =COUNTIF('Raw Data'!$K$2:$K$121,A11) -> 5 | C11: =COUNTIFS('Raw Data'!$K$2:$K$121,A11,'Raw Data'!$G$2:$G$121,"Completed") -> 4 | D11: =COUNTIFS('Raw Data'!$K$2:$K$121,A11,'Raw Data'!$G$2:$G$121,"Cancelled") -> 1 | E11: =D11/B11 -> 0.2 | F11: =SUMIFS('Raw Data'!$E$2:$E$121,'Raw Data'!$K$2:$K$121,A11,'Raw Data'!$G$2:$G$121,"Completed") -> 3393 | G11: =IFERROR(F11/C11,0) -> 848.25
A12: Johar Town -> Askari | B12: =COUNTIF('Raw Data'!$K$2:$K$121,A12) -> 3 | C12: =COUNTIFS('Raw Data'!$K$2:$K$121,A12,'Raw Data'!$G$2:$G$121,"Completed") -> 3 | D12: =COUNTIFS('Raw Data'!$K$2:$K$121,A12,'Raw Data'!$G$2:$G$121,"Cancelled") -> 0 | E12: =D12/B12 -> 0 | F12: =SUMIFS('Raw Data'!$E$2:$E$121,'Raw Data'!$K$2:$K$121,A12,'Raw Data'!$G$2:$G$121,"Completed") -> 1935 | G12: =IFERROR(F12/C12,0) -> 645
A13: Johar Town -> Cantt | B13: =COUNTIF('Raw Data'!$K$2:$K$121,A13) -> 3 | C13: =COUNTIFS('Raw Data'!$K$2:$K$121,A13,'Raw Data'!$G$2:$G$121,"Completed") -> 2 | D13: =COUNTIFS('Raw Data'!$K$2:$K$121,A13,'Raw Data'!$G$2:$G$121,"Cancelled") -> 1 | E13: =D13/B13 -> 0.33333333 | F13: =SUMIFS('Raw Data'!$E$2:$E$121,'Raw Data'!$K$2:$K$121,A13,'Raw Data'!$G$2:$G$121,"Completed") -> 1003 | G13: =IFERROR(F13/C13,0) -> 501.5
A14: Johar Town -> DHA | B14: =COUNTIF('Raw Data'!$K$2:$K$121,A14) -> 5 | C14: =COUNTIFS('Raw Data'!$K$2:$K$121,A14,'Raw Data'!$G$2:$G$121,"Completed") -> 4 | D14: =COUNTIFS('Raw Data'!$K$2:$K$121,A14,'Raw Data'!$G$2:$G$121,"Cancelled") -> 1 | E14: =D14/B14 -> 0.2 | F14: =SUMIFS('Raw Data'!$E$2:$E$121,'Raw Data'!$K$2:$K$121,A14,'Raw Data'!$G$2:$G$121,"Completed") -> 2747 | G14: =IFERROR(F14/C14,0) -> 686.75
A15: Johar Town -> Gulberg | B15: =COUNTIF('Raw Data'!$K$2:$K$121,A15) -> 3 | C15: =COUNTIFS('Raw Data'!$K$2:$K$121,A15,'Raw Data'!$G$2:$G$121,"Completed") -> 3 | D15: =COUNTIFS('Raw Data'!$K$2:$K$121,A15,'Raw Data'!$G$2:$G$121,"Cancelled") -> 0 | E15: =D15/B15 -> 0 | F15: =SUMIFS('Raw Data'!$E$2:$E$121,'Raw Data'!$K$2:$K$121,A15,'Raw Data'!$G$2:$G$121,"Completed") -> 1894 | G15: =IFERROR(F15/C15,0) -> 631.33333
A16: Johar Town -> Model Town | B16: =COUNTIF('Raw Data'!$K$2:$K$121,A16) -> 3 | C16: =COUNTIFS('Raw Data'!$K$2:$K$121,A16,'Raw Data'!$G$2:$G$121,"Completed") -> 1 | D16: =COUNTIFS('Raw Data'!$K$2:$K$121,A16,'Raw Data'!$G$2:$G$121,"Cancelled") -> 2 | E16: =D16/B16 -> 0.66666667 | F16: =SUMIFS('Raw Data'!$E$2:$E$121,'Raw Data'!$K$2:$K$121,A16,'Raw Data'!$G$2:$G$121,"Completed") -> 1054 | G16: =IFERROR(F16/C16,0) -> 1054
... A24: Wapda Town -> Model Town | B24: =COUNTIF('Raw Data'!$K$2:$K$121,A24) -> 3 | C24: =COUNTIFS('Raw Data'!$K$2:$K$121,A24,'Raw Data'!$G$2:$G$121,"Completed") -> 2 | D24: =COUNTIFS('Raw Data'!$K$2:$K$121,A24,'Raw Data'!$G$2:$G$121,"Cancelled") -> 1 | E24: =D24/B24 -> 0.33333333 | F24: =SUMIFS('Raw Data'!$E$2:$E$121,'Raw Data'!$K$2:$K$121,A24,'Raw Data'!$G$2:$G$121,"Completed") -> 1859 | G24: =IFERROR(F24/C24,0) -> 929.5

Sheet Payment Method
A1: Revenue & Cancellation by Payment Method
A3: Payment Method | B3: Total Rides | C3: Completed | D3: Cancelled | E3: Cancellation Rate | F3: Revenue | G3: Revenue % of Total | H3: Avg Fare (Completed)
A4: Card | B4: =COUNTIF('Raw Data'!$F$2:$F$121,A4) -> 45 | C4: =COUNTIFS('Raw Data'!$F$2:$F$121,A4,'Raw Data'!$G$2:$G$121,"Completed") -> 38 | D4: =COUNTIFS('Raw Data'!$F$2:$F$121,A4,'Raw Data'!$G$2:$G$121,"Cancelled") -> 7 | E4: =D4/B4 -> 0.15555556 | F4: =SUMIFS('Raw Data'!$E$2:$E$121,'Raw Data'!$F$2:$F$121,A4,'Raw Data'!$G$2:$G$121,"Completed") -> 26425 | G4: =F4/'KPI Summary'!$B$10 -> 0.40388525 | H4: =IFERROR(F4/C4,0) -> 695.39474
A5: Cash | B5: =COUNTIF('Raw Data'!$F$2:$F$121,A5) -> 42 | C5: =COUNTIFS('Raw Data'!$F$2:$F$121,A5,'Raw Data'!$G$2:$G$121,"Completed") -> 33 | D5: =COUNTIFS('Raw Data'!$F$2:$F$121,A5,'Raw Data'!$G$2:$G$121,"Cancelled") -> 9 | E5: =D5/B5 -> 0.21428571 | F5: =SUMIFS('Raw Data'!$E$2:$E$121,'Raw Data'!$F$2:$F$121,A5,'Raw Data'!$G$2:$G$121,"Completed") -> 21548 | G5: =F5/'KPI Summary'!$B$10 -> 0.32934415 | H5: =IFERROR(F5/C5,0) -> 652.9697
A6: Wallet | B6: =COUNTIF('Raw Data'!$F$2:$F$121,A6) -> 33 | C6: =COUNTIFS('Raw Data'!$F$2:$F$121,A6,'Raw Data'!$G$2:$G$121,"Completed") -> 25 | D6: =COUNTIFS('Raw Data'!$F$2:$F$121,A6,'Raw Data'!$G$2:$G$121,"Cancelled") -> 8 | E6: =D6/B6 -> 0.24242424 | F6: =SUMIFS('Raw Data'!$E$2:$E$121,'Raw Data'!$F$2:$F$121,A6,'Raw Data'!$G$2:$G$121,"Completed") -> 17454 | G6: =F6/'KPI Summary'!$B$10 -> 0.2667706 | H6: =IFERROR(F6/C6,0) -> 698.16

Sheet Fare Segment Analysis
A1: Fare-Tier Segmentation (proxy for customer segmentation)
A2: No customer ID exists in this dataset, so true ride-frequency segmentation is not possible. Rides are grouped into Low/Mid/High fare tiers instead - see Limitations.
A4: Fare Tier | B4: Rides | C4: % of Completed Rides | D4: Revenue | E4: % of Total Revenue | F4: Avg Fare
A5: Low | B5: =COUNTIFS('Raw Data'!$L$2:$L$121,A5,'Raw Data'!$G$2:$G$121,"Completed") -> 32 | C5: =B5/'KPI Summary'!$B$6 -> 0.33333333 | D5: =SUMIFS('Raw Data'!$E$2:$E$121,'Raw Data'!$L$2:$L$121,A5,'Raw Data'!$G$2:$G$121,"Completed") -> 11185 | E5: =D5/'KPI Summary'!$B$10 -> 0.17095389 | F5: =IFERROR(D5/B5,0) -> 349.53125
A6: Mid | B6: =COUNTIFS('Raw Data'!$L$2:$L$121,A6,'Raw Data'!$G$2:$G$121,"Completed") -> 32 | C6: =B6/'KPI Summary'!$B$6 -> 0.33333333 | D6: =SUMIFS('Raw Data'!$E$2:$E$121,'Raw Data'!$L$2:$L$121,A6,'Raw Data'!$G$2:$G$121,"Completed") -> 21582 | E6: =D6/'KPI Summary'!$B$10 -> 0.32986382 | F6: =IFERROR(D6/B6,0) -> 674.4375
A7: High | B7: =COUNTIFS('Raw Data'!$L$2:$L$121,A7,'Raw Data'!$G$2:$G$121,"Completed") -> 32 | C7: =B7/'KPI Summary'!$B$6 -> 0.33333333 | D7: =SUMIFS('Raw Data'!$E$2:$E$121,'Raw Data'!$L$2:$L$121,A7,'Raw Data'!$G$2:$G$121,"Completed") -> 32660 | E7: =D7/'KPI Summary'!$B$10 -> 0.49918229 | F7: =IFERROR(D7/B7,0) -> 1020.625

Sheet Scenario Analysis
A1: What-If Scenario: Cancellation Reduction & Fare Change
A2: Estimates only - not guaranteed outcomes. Edit the yellow input cells.
A4: Inputs (edit the yellow cells)
A5: Current Cancellation Rate | B5: ='KPI Summary'!B9 -> 0.2
A6: Target Cancellation Rate | B6: 0.15
A7: Current Average Fare | B7: ='KPI Summary'!B10/'KPI Summary'!B6 -> 681.53125
A8: Assumed Fare Increase % | B8: 0.05
A10: Scenario Outputs
A11: Total Rides (unchanged) | B11: ='KPI Summary'!B5 -> 120
A12: Additional Completed Rides (if cancellation drops to target) | B12: =ROUND(B11*(B5-B6),0) -> 6
A13: Estimated Extra Revenue from Fewer Cancellations | B13: =B12*B7 -> 4089.1875
A14: Estimated Revenue Impact of Fare Increase (existing completed rides) | B14: ='KPI Summary'!B10*B8 -> 3271.35
A15: Combined Estimated Revenue Uplift | B15: =B13+B14 -> 7360.5375
A16: Combined Uplift as % of Current Revenue | B16: =B15/'KPI Summary'!B10 -> 0.1125
A19: Assumptions: fare mix and demand pattern stay constant; 'target cancellation rate' assumes lost rides convert to completed rides at the current average fare; no cost data exists, so these are revenue (not profit) estimates.

Sheet DAX Measures
A1: DAX Measure Library
A2: Copy these into Power BI's Modeling > New Measure. They mirror the formulas validated on the sheets above.
A4: Measure Name | B4: DAX Formula
A5: Total Revenue | B5: Total Revenue = CALCULATE(SUM('Raw Data'[Fare]), 'Raw Data'[Ride Status] = "Completed")
A6: Completed Rides | B6: Completed Rides = CALCULATE(COUNTROWS('Raw Data'), 'Raw Data'[Ride Status] = "Completed")
A7: Cancelled Rides | B7: Cancelled Rides = CALCULATE(COUNTROWS('Raw Data'), 'Raw Data'[Ride Status] = "Cancelled")
A8: Total Rides | B8: Total Rides = COUNTROWS('Raw Data')
A9: Completion Rate | B9: Completion Rate = DIVIDE([Completed Rides], [Total Rides])
A10: Cancellation Rate | B10: Cancellation Rate = DIVIDE([Cancelled Rides], [Total Rides])
A11: Average Fare | B11: Average Fare = CALCULATE(AVERAGE('Raw Data'[Fare]), 'Raw Data'[Ride Status] = "Completed")
A12: Average Distance | B12: -- Not available: dataset has no distance column. Add one before implementing.
A13: Average Rating | B13: Average Rating = AVERAGE('Raw Data'[Rating])
A14: Revenue per Completed Ride | B14: Revenue per Completed Ride = DIVIDE([Total Revenue], [Completed Rides])
A15: Revenue (Previous Week) | B15: Revenue PW = CALCULATE([Total Revenue], DATEADD('Date Table'[Date], -7, DAY))
... A19: Revenue % of Total (Contribution) | B19: Revenue % of Total = DIVIDE([Total Revenue], CALCULATE([Total Revenue], ALL('Raw Data')))
